Workbook

Sheet Sensor
A3: System Parameters (defined by hardware) | E3: Profiles (usage of each component mode - defined by software and usage)
B4: form the datasheets
E5: "off" | F5: "sensing" | G5: "interactive"
A6: Processor | B6: DataSheet
A7: Active | B7: =28*3.3 -> 92.4 | C7: mW | E7: 0 | F7: 1 | G7: 1
A8: Idle | B8: =21*3.3 -> 69.3 | C8: mW | E8: 0 | F8: 0 | G8: 0
A9: Sleep | B9: =0.005*3.3 -> 0.0165 | C9: mW | E9: 1 | F9: 0 | G9: 0
A11: Sensor | B11: Datasheet
A12: On | B12: =0.75*3.3 -> 2.475 | C12: mW | E12: 0 | F12: 1 | G12: 1
A13: Idle | B13: =0.029*3.3 -> 0.0957 | C13: mW | E13: 1 | F13: 0 | G13: 0
A15: Radio | B15: DataSheet
A16: Data Rate | B16: 1 | C16: Mbps | E16: 0 | F16: 0 | G16: 0
A17: Standby Power | B17: 0 | C17: mW | E17: 1 | F17: 1 | G17: 0
A18: TX Power | B18: =335*3.3 -> 1105.5 | C18: mW | E18: 0 | F18: 0 | G18: 1
A19: RX Power | B19: =84*3.3 -> 277.2 | C19: mW | E19: 0 | F19: 0 | G19: 0
L20: Total power in profile (mw) | O20: Maximum Time
E21: =24-F21-G21 -> 20.4 | F21: =(1*6*60*24)/3600 -> 2.4 | G21: =(3*60*24)/3600 -> 1.2 | H21: hours/day typical usage | L21: =E5 -> "off" | M21: =SUMPRODUCT(B7:B19, E7:E19) -> 0.1122 | N21: mW | O21: =$M$26/M21 -> 22852.941 | P21: hours
A22: Battery | B22: Datasheet | L22: =F5 -> "sensing" | M22: =SUMPRODUCT(B7:B19, F7:F19) -> 94.875 | N22: mW | O22: =$M$26/M22 -> 27.026087 | P22: hours
A23: Capacity | B23: 700 | C23: mAh | L23: =G5 -> "interactive" | M23: =SUMPRODUCT(B7:B19, G7:G19) -> 1200.375 | N23: mW | O23: =$M$26/M23 -> 2.1360825 | P23: hours
A24: Nominal Voltage | B24: 3.7 | C24: V
A25: Regulator Efficiency | B25: 0.99 | L25: Effective Battery Capacity
M26: =B23*B24*B25 -> 2564.1 | N26: mW*h
L28: Days of Use | M28: =M26/(E21*M21+F21*M22+G21*M23) -> 1.5349858 | N28: days
A29: REFLECTIONS : WHAT DID YOU LEARN FROM ANALYZING YOUR POWER. TALK ABOUT SOME POTENTIAL TRADEOFFS. | L29: Hours of Use | M29: =M28*24 -> 36.83966 | N29: hours
A30: How did you determine your "days of use" metric ?
A31: What do you think is the optimum size for the battery in your device ?
A32: What hardware/software/cost/effort tradeoffs could you make to improve the user experience ?

Sheet Display
A3: System Parameters (defined by hardware) | E3: Profiles (usage of each component mode - defined by software and usage)
B4: form the datasheets
E5: "off" | F5: "sensing" | G5: "interactive"
A6: Processor | B6: DataSheet
A7: Active | B7: =28*3.3 -> 92.4 | C7: mW | E7: 0 | F7: 0 | G7: 1
A8: Idle | B8: =21*3.3 -> 69.3 | C8: mW | E8: 0 | F8: 0 | G8: 0
A9: Sleep | B9: =0.005*3.3 -> 0.0165 | C9: mW | E9: 1 | F9: 1 | G9: 0
A11: LED | B11: Datasheet
A12: On | B12: =12*3.3 -> 39.6 | C12: mW | E12: 0 | F12: 0 | G12: 1
A14: Motor | B14: Datasheet
A15: On | B15: =3.3/260*3.3*1000 -> 41.884615 | C15: mW | E15: 0 | F15: 0 | G15: 1
A16: Idle | B16: 0 | C16: mW | E16: 0 | F16: 1 | G16: 0
A17: Off | B17: 0 | C17: mW | E17: 1 | F17: 0 | G17: 0
A19: Radio | B19: DataSheet
A20: Data Rate | B20: 1 | C20: Mbps | E20: 0 | F20: 0 | G20: 0 | L20: Total power in profile (mw) | O20: Maximum Time
A21: Standby Power | B21: 0 | C21: mW | E21: 1 | F21: 1 | G21: 0 | L21: =E5 -> "off" | M21: =SUMPRODUCT(B7:B23, E7:E23) -> 0.0165 | N21: mW | O21: =$M$26/M21 -> 266400 | P21: hours
A22: TX Power | B22: =335*3.3 -> 1105.5 | C22: mW | E22: 0 | F22: 0 | G22: 0 | L22: =F5 -> "sensing" | M22: =SUMPRODUCT(B7:B23, F7:F23) -> 0.0165 | N22: mW | O22: =$M$26/M22 -> 266400 | P22: hours
A23: RX Power | B23: =84*3.3 -> 277.2 | C23: mW | E23: 0 | F23: 0 | G23: 1 | L23: =G5 -> "interactive" | M23: =SUMPRODUCT(B7:B23, G7:G23) -> 451.08462 | N23: mW | O23: =$M$26/M23 -> 9.7445132 | P23: hours
E25: =24-F25-G25 -> 22.8 | F25: =0 -> 0 | G25: =(3*60*24)/3600 -> 1.2 | H25: hours/day typical usage | L25: Effective Battery Capacity
A26: Battery | B26: Datasheet | M26: =B27*B28*B29 -> 4395.6 | N26: mW*h
A27: Capacity | B27: 1200 | C27: mAh
A28: Nominal Voltage | B28: 3.7 | C28: V | L28: Days of Use | M28: =M26/(E25*M21+F25*M22+G25*M23) -> 8.114788 | N28: days
A29: Regulator Efficiency | B29: 0.99 | L29: Hours of Use | M29: =M28*24 -> 194.75491 | N29: hours
A33: REFLECTIONS : WHAT DID YOU LEARN FROM ANALYZING YOUR POWER. TALK ABOUT SOME POTENTIAL TRADEOFFS.

Sheet Sensitivity Analysis
A50: Linked Data from First Page DO NOT EDIT
A52: =Sensor!A3 -> System Parameters (defined by hardware) | B52: =Sensor!B3 | C52: =Sensor!C3 | D52: =Sensor!D3 | T52: =Sensor!E3 -> Profiles (usage of each component mode - defined by software and usage) | U52: =Sensor!F3 | V52: =Sensor!G3 | W52: =Sensor!H3
A53: =Sensor!A4 | B53: =Sensor!B4 -> form the datasheets | C53: =Sensor!C4 | D53: =Sensor!D4 | T53: =Sensor!E4 | U53: =Sensor!F4 | V53: =Sensor!G4 | W53: =Sensor!H4
A54: =Sensor!A5 | B54: =Sensor!B5 | C54: =Sensor!C5 | D54: =Sensor!D5 | T54: =Sensor!E5 -> "off" | U54: =Sensor!F5 -> "sensing" | V54: =Sensor!G5 -> "interactive" | W54: =Sensor!H5
A55: =Sensor!A6 -> Processor | B55: =Sensor!B6 -> DataSheet | C55: =Sensor!C6 | D55: =Sensor!D6 | T55: =Sensor!E6 | U55: =Sensor!F6 | V55: =Sensor!G6 | W55: =Sensor!H6
A56: =Sensor!A7 -> Active | B56: =Sensor!B7 -> 92.4 | C56: =Sensor!C7 -> mW | D56: =$B56*0.9 -> 83.16 | E56: =$B56 -> 92.4 | F56: =$B56 -> 92.4 | G56: =$B56 -> 92.4 | H56: =$B56 -> 92.4 | I56: =$B56 -> 92.4 | J56: =$B56 -> 92.4 | K56: =$B56 -> 92.4 | L56: =$B56 -> 92.4 | ... O56: =$B56 -> 92.4 | T56: =Sensor!E7 -> 0 | U56: =Sensor!F7 -> 1 | V56: =Sensor!G7 -> 1 | W56: =Sensor!H7
A57: =Sensor!A8 -> Idle | B57: =Sensor!B8 -> 69.3 | C57: =Sensor!C8 -> mW | D57: =$B57 -> 69.3 | E57: =$B57*0.9 -> 62.37 | F57: =$B57 -> 69.3 | G57: =$B57 -> 69.3 | H57: =$B57 -> 69.3 | I57: =$B57 -> 69.3 | J57: =$B57 -> 69.3 | K57: =$B57 -> 69.3 | L57: =$B57 -> 69.3 | M57: =$B57 -> 69.3 | ... O57: =$B57 -> 69.3 | T57: =Sensor!E8 -> 0 | U57: =Sensor!F8 -> 0 | V57: =Sensor!G8 -> 0 | W57: =Sensor!H8
A58: =Sensor!A9 -> Sleep | B58: =#REF! -> #REF! | C58: =Sensor!C9 -> mW | D58: =$B58 -> #REF! | E58: =$B58 -> #REF! | F58: =$B58*0.9 -> #REF! | G58: =$B58 -> #REF! | H58: =$B58 -> #REF! | I58: =$B58 -> #REF! | J58: =$B58 -> #REF! | K58: =$B58 -> #REF! | L58: =$B58 -> #REF! | M58: =$B58 -> #REF! | N58: =$B58 -> #REF! | O58: =$B58 -> #REF! | T58: =Sensor!E9 -> 1 | U58: =Sensor!F9 -> 0 | V58: =Sensor!G9 -> 0 | W58: =Sensor!H9
A59: =Sensor!A10 | B59: =Sensor!B10 | C59: =Sensor!C10 | D59: =$B59 | E59: =$B59 | F59: =$B59 | G59: =$B59 | H59: =$B59 | I59: =$B59 | J59: =$B59 | K59: =$B59 | ... O59: =$B59 | T59: =Sensor!E10 | U59: =Sensor!F10 | V59: =Sensor!G10 | W59: =Sensor!H10
A60: =#REF! -> #REF! | B60: =#REF! -> #REF! | C60: =#REF! -> #REF! | D60: =$B60 -> #REF! | E60: =$B60 -> #REF! | F60: =$B60 -> #REF! | G60: =$B60 -> #REF! | H60: =$B60 -> #REF! | I60: =$B60 -> #REF! | J60: =$B60 -> #REF! | K60: =$B60 -> #REF! | ... O60: =$B60 -> #REF! | T60: =#REF! -> #REF! | U60: =#REF! -> #REF! | V60: =#REF! -> #REF! | W60: =#REF! -> #REF!
A61: =#REF! -> #REF! | B61: =#REF! -> #REF! | C61: =#REF! -> #REF! | D61: =$B61 -> #REF! | E61: =$B61 -> #REF! | F61: =$B61 -> #REF! | G61: =$B61*0.9 -> #REF! | H61: =$B61 -> #REF! | I61: =$B61 -> #REF! | J61: =$B61 -> #REF! | K61: =$B61 -> #REF! | L61: =$B61 -> #REF! | M61: =$B61 -> #REF! | N61: =$B61 -> #REF! | O61: =$B61 -> #REF! | T61: =#REF! -> #REF! | U61: =#REF! -> #REF! | V61: =#REF! -> #REF! | W61: =#REF! -> #REF!
A62: =#REF! -> #REF! | B62: =#REF! -> #REF! | C62: =#REF! -> #REF! | D62: =$B62 -> #REF! | E62: =$B62 -> #REF! | F62: =$B62 -> #REF! | G62: =$B62 -> #REF! | H62: =$B62 -> #REF! | I62: =$B62 -> #REF! | J62: =$B62 -> #REF! | K62: =$B62 -> #REF! | ... O62: =$B62 -> #REF! | T62: =#REF! -> #REF! | U62: =#REF! -> #REF! | V62: =#REF! -> #REF! | W62: =#REF! -> #REF!
A63: =#REF! -> #REF! | B63: =#REF! -> #REF! | C63: =#REF! -> #REF! | D63: =$B63 -> #REF! | E63: =$B63 -> #REF! | F63: =$B63 -> #REF! | G63: =$B63 -> #REF! | H63: =$B63 -> #REF! | I63: =$B63 -> #REF! | J63: =$B63 -> #REF! | K63: =$B63 -> #REF! | ... O63: =$B63 -> #REF! | T63: =#REF! -> #REF! | U63: =#REF! -> #REF! | V63: =#REF! -> #REF! | W63: =#REF! -> #REF!
A64: =Sensor!A11 -> Sensor | B64: =Sensor!B11 -> Datasheet | C64: =Sensor!C11 | D64: =$B64 -> Datasheet | E64: =$B64 -> Datasheet | F64: =$B64 -> Datasheet | G64: =$B64 -> Datasheet | H64: =$B64 -> Datasheet | I64: =$B64 -> Datasheet | J64: =$B64 -> Datasheet | K64: =$B64 -> Datasheet | ... O64: =$B64 -> Datasheet | T64: =Sensor!E11 | U64: =Sensor!F11 | V64: =Sensor!G11 | W64: =Sensor!H11
A65: =Sensor!A12 -> On | B65: =Sensor!B12 -> 2.475 | C65: =Sensor!C12 -> mW | D65: =$B65 -> 2.475 | E65: =$B65 -> 2.475 | F65: =$B65 -> 2.475 | G65: =$B65 -> 2.475 | H65: =$B65*0.9 -> 2.2275 | I65: =$B65 -> 2.475 | J65: =$B65 -> 2.475 | K65: =$B65 -> 2.475 | L65: =$B65 -> 2.475 | M65: =$B65 -> 2.475 | N65: =$B65 -> 2.475 | O65: =$B65 -> 2.475 | T65: =Sensor!E12 -> 0 | U65: =Sensor!F12 -> 1 | V65: =Sensor!G12 -> 1 | W65: =Sensor!H12
A66: =Sensor!A13 -> Idle | B66: =Sensor!B13 -> 0.0957 | C66: =Sensor!C13 -> mW | D66: =$B66 -> 0.0957 | E66: =$B66 -> 0.0957 | F66: =$B66 -> 0.0957 | G66: =$B66 -> 0.0957 | H66: =$B66 -> 0.0957 | I66: =$B66*0.9 -> 0.08613 | J66: =$B66 -> 0.0957 | K66: =$B66 -> 0.0957 | L66: =$B66 -> 0.0957 | M66: =$B66 -> 0.0957 | N66: =$B66 -> 0.0957 | O66: =$B66 -> 0.0957 | T66: =Sensor!E13 -> 1 | U66: =Sensor!F13 -> 0 | V66: =Sensor!G13 -> 0 | W66: =Sensor!H13
A67: =#REF! -> #REF! | B67: =#REF! -> #REF! | C67: =#REF! -> #REF! | D67: =$B67 -> #REF! | E67: =$B67 -> #REF! | F67: =$B67 -> #REF! | G67: =$B67 -> #REF! | H67: =$B67 -> #REF! | I67: =$B67 -> #REF! | J67: =$B67*0.9 -> #REF! | K67: =$B67 -> #REF! | L67: =$B67 -> #REF! | M67: =$B67 -> #REF! | N67: =$B67 -> #REF! | O67: =$B67 -> #REF! | T67: =#REF! -> #REF! | U67: =#REF! -> #REF! | V67: =#REF! -> #REF! | W67: =#REF! -> #REF!
A68: =Sensor!A14 | B68: =Sensor!B14 | C68: =Sensor!C14 | D68: =$B68 | E68: =$B68 | F68: =$B68 | G68: =$B68 | H68: =$B68 | I68: =$B68 | J68: =$B68 | K68: =$B68 | ... O68: =$B68 | T68: =Sensor!E14 | U68: =Sensor!F14 | V68: =Sensor!G14 | W68: =Sensor!H14
A69: =#REF! -> #REF! | B69: =#REF! -> #REF! | C69: =#REF! -> #REF! | D69: =$B69 -> #REF! | E69: =$B69 -> #REF! | F69: =$B69 -> #REF! | G69: =$B69 -> #REF! | H69: =$B69 -> #REF! | I69: =$B69 -> #REF! | J69: =$B69 -> #REF! | K69: =$B69 -> #REF! | ... O69: =$B69 -> #REF! | T69: =#REF! -> #REF! | U69: =#REF! -> #REF! | V69: =#REF! -> #REF! | W69: =#REF! -> #REF!
A70: =#REF! -> #REF! | B70: =#REF! -> #REF! | C70: =#REF! -> #REF! | D70: =$B70 -> #REF! | E70: =$B70 -> #REF! | F70: =$B70 -> #REF! | G70: =$B70 -> #REF! | H70: =$B70 -> #REF! | I70: =$B70 -> #REF! | J70: =$B70 -> #REF! | K70: =$B70*0.9 -> #REF! | L70: =$B70 -> #REF! | M70: =$B70 -> #REF! | N70: =$B70 -> #REF! | O70: =$B70 -> #REF! | T70: =#REF! -> #REF! | U70: =#REF! -> #REF! | V70: =#REF! -> #REF! | W70: =#REF! -> #REF!
A71: =#REF! -> #REF! | B71: =#REF! -> #REF! | C71: =#REF! -> #REF! | D71: =$B71 -> #REF! | E71: =$B71 -> #REF! | F71: =$B71 -> #REF! | G71: =$B71 -> #REF! | H71: =$B71 -> #REF! | I71: =$B71 -> #REF! | J71: =$B71 -> #REF! | K71: =$B71 -> #REF! | L71: =$B71*0.9 -> #REF! | M71: =$B71 -> #REF! | N71: =$B71 -> #REF! | O71: =$B71 -> #REF! | T71: =#REF! -> #REF! | U71: =#REF! -> #REF! | V71: =#REF! -> #REF! | W71: =#REF! -> #REF!
A72: =#REF! -> #REF! | B72: =#REF! -> #REF! | C72: =#REF! -> #REF! | D72: =$B72 -> #REF! | E72: =$B72 -> #REF! | F72: =$B72 -> #REF! | G72: =$B72 -> #REF! | H72: =$B72 -> #REF! | I72: =$B72 -> #REF! | J72: =$B72 -> #REF! | K72: =$B72 -> #REF! | ... O72: =$B72 -> #REF! | T72: =#REF! -> #REF! | U72: =#REF! -> #REF! | V72: =#REF! -> #REF! | W72: =#REF! -> #REF!
A73: =Sensor!A15 -> Radio | B73: =Sensor!B15 -> DataSheet | C73: =Sensor!C15 | D73: =$B73 -> DataSheet | E73: =$B73 -> DataSheet | F73: =$B73 -> DataSheet | G73: =$B73 -> DataSheet | H73: =$B73 -> DataSheet | I73: =$B73 -> DataSheet | J73: =$B73 -> DataSheet | K73: =$B73 -> DataSheet | ... O73: =$B73 -> DataSheet | T73: =Sensor!E15 | U73: =Sensor!F15 | V73: =Sensor!G15 | W73: =Sensor!H15
A74: =Sensor!A17 -> Standby Power | B74: =Sensor!B17 -> 0 | C74: =Sensor!C17 -> mW | D74: =$B74 -> 0 | E74: =$B74 -> 0 | F74: =$B74 -> 0 | G74: =$B74 -> 0 | H74: =$B74 -> 0 | I74: =$B74 -> 0 | J74: =$B74 -> 0 | K74: =$B74 -> 0 | L74: =$B74 -> 0 | M74: =$B74*0.9 -> 0 | N74: =$B74 -> 0 | O74: =$B74 -> 0 | T74: =Sensor!E17 -> 1 | U74: =Sensor!F17 -> 1 | V74: =Sensor!G17 -> 0 | W74: =Sensor!H17
A75: =Sensor!A18 -> TX Power | B75: =Sensor!B18 -> 1105.5 | C75: =Sensor!C18 -> mW | D75: =$B75 -> 1105.5 | E75: =$B75 -> 1105.5 | F75: =$B75 -> 1105.5 | G75: =$B75 -> 1105.5 | H75: =$B75 -> 1105.5 | I75: =$B75 -> 1105.5 | J75: =$B75 -> 1105.5 | K75: =$B75 -> 1105.5 | ... M75: =$B75 -> 1105.5 | N75: =$B75*0.9 -> 994.95 | O75: =$B75 -> 1105.5 | T75: =Sensor!E18 -> 0 | U75: =Sensor!F18 -> 0 | V75: =Sensor!G18 -> 1 | W75: =Sensor!H18
A76: =Sensor!A19 -> RX Power | B76: =Sensor!B19 -> 277.2 | C76: =Sensor!C19 -> mW | D76: =$B76 -> 277.2 | E76: =$B76 -> 277.2 | F76: =$B76 -> 277.2 | G76: =$B76 -> 277.2 | H76: =$B76 -> 277.2 | I76: =$B76 -> 277.2 | J76: =$B76 -> 277.2 | K76: =$B76 -> 277.2 | ... N76: =$B76 -> 277.2 | O76: =$B76*0.9 -> 249.48 | T76: =Sensor!E19 -> 0 | U76: =Sensor!F19 -> 0 | V76: =Sensor!G19 -> 0 | W76: =Sensor!H19
A77: =Sensor!A20 | B77: =Sensor!B20 | C77: =Sensor!C20 | D77: =Sensor!D20 | T77: =Sensor!E20 | U77: =Sensor!F20 | V77: =Sensor!G20 | W77: =Sensor!H20
A78: =Sensor!A21 | B78: =Sensor!B21 | C78: =Sensor!C21 | D78: =Sensor!D21 | T78: =Sensor!E21 -> 20.4 | U78: =Sensor!F21 -> 2.4 | V78: =Sensor!G21 -> 1.2 | W78: =Sensor!H21 -> hours/day typical usage
A79: =Sensor!A22 -> Battery | B79: =Sensor!B22 -> Datasheet | C79: =Sensor!C22 | D79: =Sensor!D22 | T79: =Sensor!E22 | U79: =Sensor!F22 | V79: =Sensor!G22 | W79: =Sensor!H22
A80: =Sensor!A23 -> Capacity | B80: =Sensor!B23 -> 700 | C80: =Sensor!C23 -> mAh | D80: =Sensor!D23 | T80: =Sensor!E23 | U80: =Sensor!F23 | V80: =Sensor!G23 | W80: =Sensor!H23
A81: =Sensor!A24 -> Nominal Voltage | B81: =Sensor!B24 -> 3.7 | C81: =Sensor!C24 -> V | D81: =Sensor!D24 | T81: =Sensor!E24 | U81: =Sensor!F24 | V81: =Sensor!G24 | W81: =Sensor!H24
A82: =Sensor!A25 -> Regulator Efficiency | B82: =Sensor!B25 -> 0.99 | C82: =Sensor!C25 | D82: =Sensor!D25 | T82: =Sensor!E25 | U82: =Sensor!F25 | V82: =Sensor!G25 | W82: =Sensor!H25
A83: =Sensor!A26 | B83: =Sensor!B26 | C83: =Sensor!C26 | D83: =Sensor!D26 | O83: =Sensor!E26 | P83: =Sensor!F26 | Q83: =Sensor!G26 | R83: =Sensor!H26 | S83: =Sensor!I26 | T83: =Sensor!J30 | U83: =#REF! -> #REF! | V83: =#REF! -> #REF!
A84: =Sensor!A27 | B84: =Sensor!B27 | C84: =Sensor!C27 | D84: =Sensor!D27 | O84: =Sensor!E27 | P84: =Sensor!F27 | Q84: =Sensor!G27 | R84: =Sensor!H27 | S84: =Sensor!I27 | T84: =Sensor!J31 | U84: =#REF! -> #REF! | V84: =#REF! -> #REF!
A85: =Sensor!A28 | B85: =Sensor!K19 | C85: =Sensor!L19 | D85: =Sensor!M19 | O85: =Sensor!N19 | P85: =Sensor!O19 | Q85: =Sensor!P19 | R85: =Sensor!Q19 | S85: =Sensor!I28 | T85: =#REF! -> #REF! | U85: =#REF! -> #REF! | V85: =#REF! -> #REF!
A86: =Sensor!A29 -> REFLECTIONS : WHAT DID YOU LEARN FROM ANALYZING YOUR POWER. TALK ABOUT SOME POTENTIAL TRADEOFFS. | B86: =Sensor!K20 | C86: =#REF! -> #REF! | D86: =#REF! -> #REF! | O86: =#REF! -> #REF! | P86: =#REF! -> #REF! | Q86: =#REF! -> #REF! | R86: =Sensor!Q20 | S86: =Sensor!I29 | T86: =#REF! -> #REF! | U86: =#REF! -> #REF! | V86: =#REF! -> #REF!
A87: =Sensor!L20 -> Total power in profile (mw) | B87: =Sensor!M20 | C87: =Sensor!N20 | R87: =Sensor!Q21 | S87: =Sensor!I30 | T87: =#REF! -> #REF! | U87: =#REF! -> #REF! | V87: =#REF! -> #REF!
A88: =Sensor!L21 -> "off" | B88: =sumproduct(B56:B76, $T56:$T76) -> #REF! | C88: =Sensor!N21 -> mW | D88: =sumproduct(D56:D76, $T56:$T76) -> #REF! | E88: =sumproduct(E56:E76, $T56:$T76) -> #REF! | F88: =sumproduct(F56:F76, $T56:$T76) -> #REF! | G88: =sumproduct(G56:G76, $T56:$T76) -> #REF! | H88: =sumproduct(H56:H76, $T56:$T76) -> #REF! | I88: =sumproduct(I56:I76, $T56:$T76) -> #REF! | J88: =sumproduct(J56:J76, $T56:$T76) -> #REF! | K88: =sumproduct(K56:K76, $T56:$T76) -> #REF! | ... O88: =sumproduct(O56:O76, $T56:$T76) -> #REF! | R88: =Sensor!Q22 | S88: =Sensor!I31 | T88: =#REF! -> #REF! | U88: =#REF! -> #REF! | V88: =#REF! -> #REF!
A89: =Sensor!L22 -> "sensing" | B89: =sumproduct(B56:B76,$U56:$U76) -> #REF! | C89: =Sensor!N22 -> mW | D89: =sumproduct(D56:D76,$U56:$U76) -> #REF! | E89: =sumproduct(E56:E76,$U56:$U76) -> #REF! | F89: =sumproduct(F56:F76,$U56:$U76) -> #REF! | G89: =sumproduct(G56:G76,$U56:$U76) -> #REF! | H89: =sumproduct(H56:H76,$U56:$U76) -> #REF! | I89: =sumproduct(I56:I76,$U56:$U76) -> #REF! | J89: =sumproduct(J56:J76,$U56:$U76) -> #REF! | K89: =sumproduct(K56:K76,$U56:$U76) -> #REF! | ... O89: =sumproduct(O56:O76,$U56:$U76) -> #REF! | R89: =Sensor!Q23 | S89: =Sensor!I32 | T89: =Sensor!J32 | U89: =Sensor!K32 | V89: =Sensor!L32
A90: =Sensor!L23 -> "interactive" | B90: =sumproduct(B56:B76, $V56:$V76) -> #REF! | C90: =Sensor!N23 -> mW | D90: =sumproduct(D56:D76, $V56:$V76) -> #REF! | E90: =sumproduct(E56:E76, $V56:$V76) -> #REF! | F90: =sumproduct(F56:F76, $V56:$V76) -> #REF! | G90: =sumproduct(G56:G76, $V56:$V76) -> #REF! | H90: =sumproduct(H56:H76, $V56:$V76) -> #REF! | I90: =sumproduct(I56:I76, $V56:$V76) -> #REF! | J90: =sumproduct(J56:J76, $V56:$V76) -> #REF! | K90: =sumproduct(K56:K76, $V56:$V76) -> #REF! | ... O90: =sumproduct(O56:O76, $V56:$V76) -> #REF! | R90: =Sensor!Q24 | S90: =Sensor!I33 | T90: =Sensor!J33 | U90: =Sensor!K33 | V90: =Sensor!L33
...
